<?xml version="1.0" ?>
<!-- =================================================================================== -->
<!-- |    This document was autogenerated by xacro from /home/sini_ros/urdf_ws/src/robot_description/urdf/description.urdf.xacro | -->
<!-- |    EDITING THIS FILE BY HAND IS NOT RECOMMENDED                                 | -->
<!-- =================================================================================== -->
<robot name="robot_demo">
  <link name="world"/>
  <link name="base_link">
    <visual>
      <origin rpy="0 0 0" xyz="0 0 0.1"/>
      <geometry>
        <cylinder length="0.2" radius="0.2"/>
        <!--<mesh filename="package://robot_description/meshes/Base.STL"/>-->
      </geometry>
    </visual>
  </link>
  <joint name="base_joint" type="fixed">
    <parent link="world"/>
    <child link="base_link"/>
    <origin rpy="0 0 0" xyz="0 0 0"/>
  </joint>
  <link name="base_plate">
    <visual>
      <origin rpy="0 0 0" xyz="0 0 0.025"/>
      <geometry>
        <cylinder length="0.05" radius="0.2"/>
      </geometry>
    </visual>
  </link>
  <joint name="base_plate_joint" type="revolute">
    <parent link="base_link"/>
    <child link="base_plate"/>
    <axis xyz="0 0 1"/>
    <origin rpy="0 0 0" xyz="0 0 0.2"/>
    <limit effort="30.0" lower="-1.5707" upper="1.5707" velocity="10.0"/>
  </joint>
  <link name="support_base_1">
    <visual>
      <origin rpy="0 0 0" xyz="0 0 0.09"/>
      <geometry>
        <box size="0.15 0.15 0.1"/>
      </geometry>
    </visual>
  </link>
  <joint name="support_joint_1" type="fixed">
    <parent link="base_plate"/>
    <child link="support_base_1"/>
    <origin rpy="0 0 0" xyz="0.14 0 0"/>
  </joint>
  <link name="support_base_2">
    <visual>
      <origin rpy="0 0 0" xyz="0 0 0.09"/>
      <geometry>
        <box size="0.15 0.15 0.1"/>
      </geometry>
    </visual>
  </link>
  <joint name="support_joint_2" type="fixed">
    <parent link="base_plate"/>
    <child link="support_base_2"/>
    <origin rpy="0 0 0" xyz="-0.14 0 0"/>
  </joint>
  <link name="verticle_link">
    <visual>
      <origin rpy="0 0 0" xyz="0 0 0.13"/>
      <geometry>
        <box size="0.09 0.1 0.3"/>
      </geometry>
    </visual>
  </link>
  <joint name="vertical_joint" type="revolute">
    <parent link="support_base_1"/>
    <child link="verticle_link"/>
    <origin rpy="0 0 0" xyz="-0.14 0 0.1"/>
    <axis xyz="1 0 0"/>
    <limit effort="30.0" lower="-1.5707" upper="1.5707" velocity="10.0"/>
  </joint>
  <link name="verticle_support_link_1">
    <visual>
      <origin rpy="0 0 0" xyz="0 0 0"/>
      <geometry>
        <box size="0.09 0.1 0.1"/>
      </geometry>
    </visual>
  </link>
  <joint name="vertical_support_joint_1" type="fixed">
    <parent link="verticle_link"/>
    <child link="verticle_support_link_1"/>
    <origin rpy="0 0 0" xyz="-0.09 0 0.30"/>
  </joint>
  <link name="verticle_support_link_2">
    <visual>
      <origin rpy="0 0 0" xyz="0 0 0"/>
      <geometry>
        <box size="0.09 0.1 0.1"/>
      </geometry>
    </visual>
  </link>
  <joint name="vertical_support_joint_2" type="fixed">
    <parent link="verticle_link"/>
    <child link="verticle_support_link_2"/>
    <origin rpy="0 0 0" xyz="0.09 0 0.30"/>
  </joint>
  <link name="forward_link">
    <visual>
      <origin rpy="0 0 0" xyz="0 0 0.17"/>
      <geometry>
        <box size="0.09 0.1 0.3"/>
      </geometry>
    </visual>
  </link>
  <joint name="forwaed_joint" type="revolute">
    <parent link="verticle_support_link_1"/>
    <child link="forward_link"/>
    <origin rpy="0 0 0" xyz="0.09 0 0"/>
    <axis xyz="1 0 0"/>
    <limit effort="30.0" lower="-1.5707" upper="1.5707" velocity="10.0"/>
  </joint>
</robot>
